<mujoco model="param_reacher">
    <compiler angle="radian" />
    <default>
        <geom contype="0" friction="1 0.1 0.1" rgba="0.7 0.7 0 1" />
    </default>
    <asset>
        <mesh file="boundary.STL" />
        <mesh file="fingertip.STL" />
        <mesh file="link0.STL" />
        <mesh file="link1.STL" />
        <mesh file="link2.STL" />
    </asset>
    <worldbody>
        <body>
            <geom mesh="boundary" name="boundary" pos="0 0 0" type="mesh" />
        </body>
        <body name="link0" pos="0 0 0">
            <geom conaffinity="2" contype="2" mesh="link0" name="link0" pos="0 0 0" type="mesh" />
            <body name="link1" pos="0 0 0">
                <joint axis="0 0 1" name="joint0" pos="0.0 0 0" />
                <geom conaffinity="2" mesh="link1" name="link1" pos="0 0 0" type="mesh" />
                <body name="link2" pos="0 0 0">
                    <joint axis="0 0 1" limited="true" name="joint1" pos="0.11 0 0" range="-3.0 3.0" />
                    <geom conaffinity="2" mesh="link2" name="link2" pos="0 0 0" type="mesh" />
                    <body name="fingertip" pos="0 0 0" />
                    <geom conaffinity="2" contype="2" mesh="fingertip" name="fingertip" pos="0 0 0" type="mesh" />
                </body>
            </body>
        </body>
        <body name="target">
            <geom conaffinity="0" contype="1" name="target" pos="0.032 -0.036 0" rgba="0.8 0.2 0.2 1" size="0.01" type="sphere" />
        </body>
    </worldbody>
    <actuator>
        
        <velocity ctrllimited="true" ctrlrange="-1.0 1.0" gear="0.05" joint="joint0" />
        <velocity ctrllimited="true" ctrlrange="-1.0 1.0" gear="0.05" joint="joint1" />
    </actuator>
</mujoco>